Workbook
Name __xlnm._FilterDatabase_1: CONTROLES_PLANO!$AH$4:$AH$10090
Name __xlnm._FilterDatabase_2: RISCOS_RESIDUAIS!$AW$4:$AW$10090
Name __xlnm._FilterDatabase_3: TRATAMENTO!$AI$4:$AI$10090
Name AMEACAS: AMEACAS!$D$2:$D$45
Name CONSEQ_1: AVALIAR_RISCO!$K$10085:$K$10095
Name CONSEQ_10: CONSEQUENCIAS!$H$10084:$H$10094
Name CONSEQ_2: CALCULO_RISCO!$K$10085:$K$10095
Name CONSEQ_3: CONS_AV_QUALIT_ATIVO!$H$10084:$H$10094
Name CONSEQ_4: CONS_AV_QUALIT_PROBAB!$F$10085:$F$10095
Name CONSEQ_5: #N/A
Name CONSEQ_6: CONTROLES_PLANO!$I$10084:$I$10094
Name CONSEQ_7: RESULT_ESTIMAT_QUALIT!$F$10084:$F$10094
Name CONSEQ_8: RISCOS_RESIDUAIS!$I$10084:$I$10094
Name CONSEQ_9: TRATAMENTO!$K$10084:$K$10094
Name DECISÃO: #N/A
Name EXISTEM_RISCOS_RESIDUAIS?: #N/A
Name impacto: #REF!
Name prio: ESTIMATIVA!$N$53:$N$60
Name prioridade: CRITÉRIOS!$M$78:$M$85
Name probabil: #REF!
Name probabilidade: CRITÉRIOS!$F$25:$F$30
Name rele_ativo: CRITÉRIOS!$F$36:$F$41
Name residual: ACEITAÇÃO_RISCO!$A$11019:$A$11021
Name residual_1: RISCOS_RESIDUAIS!$A$11019:$A$11021
Name Rest_Escopo: Restrições!$B$11096:$B$11102
Name Rest_Escopo1: Restrições!$B$11095:$B$11102
Name Rest_organ: Restrições!$A$11096:$A$11106
Name Rest_Organ1: Restrições!$A$11095:$A$11106
Name severidade: CRITÉRIOS!$F$47:$F$52
Name tratar_1: #N/A
Name tratar_2: #N/A
Name tratar_3: #N/A

Sheet INICIO
B27: Exercício Prático | I27: NOME: GUSTAVO PEREIRA DE FARIA
B28: Sessão 2 | I28: NOME: EMERSON CARLOS BEGUETTO
B29: Sessão 3 | I29: NOME: CARLOS EDUARDO BENTO DA SILVA
B30: Sessão 4
B31: Sessão 5
B32: Sessão 6
B33: Sessão 7
B34: Sessão 8
B35: Sessão 9
B36: Sessão 10

Sheet SESSAO_2
A1: Gestão de Riscos de TI – NBR 27005
A3: Sessão 2
A6: OBJETIVO: Aplicar num exercício os conhecimentos adquiridos na sessão 2. Compreender e desenvolver o início de um processo de análise de risco.
A10: Nas quatro atividades que fazem parte desta sessão, serão vistos os conceitos apreendidos na sessão 2. | J10: Atividades – Sessão 2
J11: 2.1 Defina o Contexto
A13: Lembre-se: estas atividades devem ser feitas na sequência e com o acompanhamento da norma 27005. | J13: 2.2 Identifique Restrições
J15: 2.3 Defina o Escopo
A16: Qualquer dúvida pergunte ao instrutor!!
J17: 2.4 Defina os Critérios

Sheet Definir_Contexto
A4: Propósito principal da organização | E4: Fornecer soluções tecnológicas seguras, modernas e eficientes para proteger dados, otimizar processos e impulsionar o crescimento digital das empresas.
A12: Negócio da organização | E12: Serviços de tecnologia da informação com foco em segurança da informação e soluções em nuvem.
A20: A sua missão | E20: Proteger e fortalecer a infraestrutura tecnológica dos nossos clientes, oferecendo soluções inovadoras, seguras e de alta qualidade que garantam continuidade, confiabilidade e competitividade no ambiente digital.
A27: Seus valores | E27: Integridade e ética Segurança e confidencialidade Inovação contínua Transparência Compromisso com o cliente Qualidade nos serviços Responsabilidade social e ambiental
A35: A estrutura da organização | E35: A NexaTech é estruturada em setores funcionais, cada um com responsabilidades específicas, sob coordenação da Diretoria Executiva: Diretoria Executiva TI e Infraestrutura Segurança da Informação Desenvolvimento de Sistemas Suporte Técnico (Help Desk) Comercial e Marketing Recursos Humanos (RH) Financeiro
A43: Organograma | E43: Diretoria Executiva Gerência de TI e Infraestrutura Equipe de Redes Equipe de Servidores e Cloud Gerência de Segurança da Informação Analistas de SOC Time de Pentest Gerência de Desenvolvimento de Sistemas Desenvolvedores Front-end Desenvolvedores Back-end Gerência de Suporte Técnico Técnicos de Help Desk Gerência Comercial e Marketing Gerência de Recursos Humanos Gerência Financeira
A51: Estratégias | E51: Expansão nacional dos serviços de segurança e nuvem Investimento em tecnologias avançadas de proteção (SIEM, EDR, SOAR) Parcerias com provedores de nuvem (AWS, Azure, Google Cloud) Fortalecimento do SOC (Security Operations Center) Automação de processos internos Crescimento no mercado de pequenas e médias empresas
A59: Qual o setor que solicitou o projeto? Qual o seu nível hierárquico dentro do organograma? A quem esta subordinado? | E59: Setor que solicitou: Segurança da Informação Nível Hierarquico: Analista de Segurança da Informação – Nível Júnior Subordinado: Gerente de Segurança da Informação
A67: Qual ou quais os principais processos de negócio da organização? | E67: Monitoramento de segurança (SOC) Gestão de incidentes Consultoria em segurança Implantação de soluções em nuvem Desenvolvimento de sistemas Suporte técnico ao cliente Testes de invasão (Pentest) Backup e recuperação de dados Comercialização e atendimento ao cliente
A75: Quais os requisitos legais ou regulatórios a que a organização esta sujeita? | E75: A NexaTech segue legislações e normas aplicáveis ao setor de TI: Lei Geral de Proteção de Dados (LGPD – Lei 13.709/2018) Marco Civil da Internet (Lei 12.965/2014) Código de Defesa do Consumidor Normas ISO 27001 e 27002 (boas práticas de segurança) Contratos de confidencialidade (NDA) Regulamentações específicas dos clientes (quando aplicável) Direitos trabalhistas (CLT) Lei do Backup (quando aplicável em setores regulados)
A83: Quais os seus principais produtos | E83: Implantação de Cloud Computing Serviço de Monitoramento (SOC 24/7) Pentest (Web, Rede, Mobile) Consultoria em Segurança Desenvolvimento de sistemas Backup e Disaster Recovery Suporte Técnico
A91: Quais os seus fornecedores principais | E91: Provedores de nuvem: AWS, Microsoft Azure, Google Cloud Fornecedores de software de segurança: Fortinet, Kaspersky, CrowdStrike Fabricantes de infraestrutura: Dell, Cisco, Lenovo Serviços terceirizados de suporte e manutenção
... A107: Quais os requisitos legais ou regulatórios a que a organização esta sujeita? | E107: LGPD Marco Civil Normas ISO 27001 CLT Normas do setor financeiro quando atende fintechs Contratos de confidencialidade com clientes e parceiros

Sheet Restrições
A1: Análise das Restrições
A4: Restrições que afetam a organização | B4: Restrições | J4: Justificativa
B5: advindas da agenda da organização | J5: A NexaTech possui um cronograma interno rígido para implantação de projetos, priorizando contratos já ativos, atividades do SOC 24/7 e demandas críticas de segurança. Isso limita a disponibilidade imediata de equipes e recursos para novos projetos, impactando prazos e priorização
B7: advindas do ambiente economico e político | J7: A empresa depende de tecnologias importadas e de fornecedores estrangeiros (Microsoft, AWS, Google), ficando sujeita à variação cambial e instabilidade econômica. Mudanças na legislação de proteção de dados ou políticas governamentais podem impactar custos, compliance e prazos.
B9: de natureza cultural | J9: A cultura organizacional altamente técnica da NexaTech prioriza segurança, processos formais e validações rigorosas. Isso faz com que mudanças, novas metodologias ou novas práticas precisem de avaliação prévia extensa, dificultando adoções rápidas.
B11: de natureza estratégica | J11: O foco estratégico da empresa é expansão do SOC e fortalecimento em cloud. Projetos que não se alinham diretamente a essa visão podem receber menos recursos, tempo ou prioridade, limitando sua execução rápida ou plena.
B13: relacionadas a métodos | J13: A organização utiliza metodologias específicas (ITIL, ISO 27001, OWASP, métodos formais de análise de risco), exigindo padronização e documentação rígida. Isso pode restringir métodos alternativos, abordagens informais ou práticas não alinhadas ao SGSI.
B15: estruturais | J15: A estrutura organizacional com múltiplos níveis (Diretoria → Gerências → Coordenações Analistas) exige fluxo formal de aprovações. Isso pode prolongar decisões, impactar prazos e limitar mudanças inesperadas nos processos.
B17: funcionais | J17: Algumas áreas funcionam com equipes reduzidas (ex.: Desenvolvimento, Help Desk N3), o que restringe a realocação de profissionais e a disponibilidade simultânea para todos os projetos. Essa limitação afeta escalabilidade interna.
A21: Restrições que afetam o escopo | B21: RESTRIÇÕES | J21: JUSTIFICATIVA
B22: ambientais | J22: Os serviços dependem de infraestrutura em nuvem, links estáveis e ambientes controlados. Qualquer limitação física ou de conectividade no cliente ou na própria NexaTech afeta escopo, testes e atividades de implantação.
B24: derivadas de processos preexistentes | J24: Alguns clientes possuem sistemas legados, documentação desatualizada ou integração limitada, o que exige adaptações e pode limitar escopo, impedindo automações ou integrações completas.
B26: financeiras | J26: A alocação de orçamento é controlada e depende de aprovação do setor financeiro e diretoria. Nem sempre o projeto recebe recursos imediatos para novas ferramentas, treinamentos ou contratação de consultores externos, restringindo escopo e velocidade.
B28: organizacionais | J28: Regras internas de segurança, compliance, LGPD e a certificação ISO 27001 impõem controles obrigatórios, impactando prazos, métodos, ferramentas permitidas e tipos de dados que podem ser manipulados no projeto.
B30: técnicas | J30: A NexaTech depende de tecnologias específicas, como plataformas de nuvem (AWS, Azure, Google Cloud), SIEM corporativo e ferramentas de segurança certificadas. Algumas integrações podem ser limitadas pela arquitetura atual do cliente, por sistemas legados ou por incompatibilidade de versões. Além disso, certos recursos avançados exigem licenças adicionais, o que restringe o escopo técnico possível no projeto.
B32: temporais | J32: O escopo pode ser limitado pela disponibilidade de equipes especializadas (SOC, Pentest, Cloud), que trabalham com agendas cheias e atendem contratos simultâneos. Muitos serviços precisam ser executados fora do horário comercial para evitar indisponibilidade, reduzindo as janelas de execução. Também existem prazos contratuais rígidos e SLAs que impedem prolongamento ou expansão do projeto sem negociação formal
B34: relacionadas a métodos | J34: A empresa segue metodologias formais como ISO 27001, ITIL, COBIT e padrões OWASP. Isso exige processos documentados, análises formais de risco, testes controlados e aprovação de mudanças via Change Management. Por esse motivo, métodos alternativos ou abordagens ágeis demais podem não ser permitidos, restringindo como o escopo pode ser executado e quais técnicas podem ser utilizadas.
A11095: ESCOLHA A OPÇÃO | B11095: ESCOLHA A OPÇÃO
A11096: advindas da agenda da organização | B11096: ambientais
A11097: advindas do ambiente economico e político | B11097: derivadas de processos preexistentes
A11098: de natureza cultural | B11098: financeiras
A11099: de natureza estratégica | B11099: organizacionais
A11100: de natureza política | B11100: relacionadas a métodos
A11101: estruturais | B11101: técnicas
A11102: funcionais | B11102: temporais
A11103: orçamentárias
A11104: relacionadas a métodos
A11105: relativas aos recursos humanos
A11106: territoriais

Sheet Escopo
A1: Definição do Escopo
A4: Descrição do escopo | E4: O escopo abrange todas as atividades relacionadas à prestação de serviços de Segurança da Informação, Infraestrutura em Nuvem e Monitoramento (SOC), incluindo implantação de soluções tecnológicas, desenvolvimento de sistemas personalizados, suporte técnico, gestão de ambientes cloud e execução de testes de segurança. Inclui também todos os processos administrativos e operacionais que dão suporte direto a essas atividades.
A12: Seu entendimento do escopo (da equipe de risco - explique o escopo) | E12: A equipe de gestão de riscos será responsável por: Identificar, analisar e avaliar riscos relacionados aos serviços de segurança e TI. Avaliar vulnerabilidades em processos, sistemas e ativos. Monitorar controles existentes e apontar necessidades de melhoria. Apoiar na tomada de decisão para priorização do tratamento de riscos. Garantir alinhamento com boas práticas (ISO 27001, 27005, LGPD). O foco é proteger dados dos clientes e da própria NexaTech, garantindo confiabilidade, disponibilidade e integridade.
A20: Quais os departamentos (áreas/gerencias) envolvidas / abrangidas pelo escopo? | E20: Os seguintes setores estão dentro do escopo: Departamentos Técnicos Segurança da Informação (SOC, análise, gestão de vulnerabilidades) TI e Infraestrutura Desenvolvimento de Sistemas Suporte Técnico / Help Desk Departamentos de Apoio Comercial (por lidar com dados de clientes) Financeiro (por processar informações sensíveis) Recursos Humanos (por administrar dados pessoais e confidenciais) Diretoria Executiva Incluída por decisões estratégicas e validação de políticas.
A28: Quais os processos e sistemas envolvidos / abrangidos pelo escopo? | E28: Processos envolvidos Monitoramento 24/7 de redes (SOC) Atendimento técnico e suporte Gestão de acessos e identidades Desenvolvimento seguro de software Implantação de soluções em nuvem Gestão de vulnerabilidades Gestão de backups e recuperação de desastres Processos de comunicação interna e gestão documental Gestão de contratos e relacionamento com clientes Sistemas envolvidos Plataforma de Cloud (AWS/Azure/GCP) Sistemas internos de gestão de clientes (CRM) Ferramentas de ticket (Help Desk) Ferramentas SIEM Firewalls, IDS/IPS Servidores internos e banco de dados Repositórios de código (GitLab/GitHub)
A36: Quantas pessoas (Recursos Humanos) envolvidos / abrangidos pelo escopo? | E36: Aproximadamente 85 funcionários, sendo: 70 funcionários próprios 15 terceirizados (suporte, infraestrutura, limpeza e segurança) Todos que lidam com dados, sistemas ou processos críticos estão incluídos. no RH
A44: Quantos ativos envolvidos/abrangidos pelo escopo? Aproximado | E44: Estimativa aproximada: Ativos físicos 90 estações de trabalho 12 servidores cloud 6 switches gerenciáveis 4 firewalls corporativos Ativos de software 15 sistemas e plataformas críticas 8 ferramentas de segurança 5 aplicativos internos Ativos informacionais Documentação técnica Políticas internas Dados de clientes Logs e relatórios do SOC Códigos-fonte de projetos Total aproximado: entre 120 e 150 ativos.
A52: Quais os limites do escopo? | E52: Processos e sistemas que suportam a entrega dos serviços da NexaTech Ambientes internos (nuvem, servidores, redes, estações) Pessoas envolvidas em processos críticos Dados tratados ou armazenados pela empresa Infraestrutura utilizada na operação do SOC e demais serviços Processos administrativos diretamente ligados às operações
A60: O que não faz parte do escopo? JUSTIFIQUE | E60: Estão fora do escopo: Sistemas e ambientes de uso pessoal dos colaboradores Processos terceirizados que não tratem dados da empresa Equipamentos pessoais (BYOD) Atividades externas que a NexaTech NÃO executa diretamente Sistemas de parceiros ou fornecedores que não integram os serviços Ambientes domésticos de colaboradores em home office Serviços fora do portfólio da empresa

Sheet CRITÉRIOS
A1: Critérios para Avaliação de Riscos
C4: Critério de Probabilidade
C5: Nível | F5: Definição
C6: Frequente | F6: Tem ocorrido pelo menos uma vez a cada mês
C7: Provável | F7: É possível de ocorrer a cada 6 meses ou menos. Nos últimos seis meses já ocorreu
C8: Ocasional | F8: Nos último ano já ocorreu pelo menos 1 vezes
C9: Remoto | F9: Nos últimos cinco anos já ocorreu pelo menos 3 vezes
C10: Improvável | F10: Nunca ocorreu.
J11: 2.1 Defina o Contexto
C12: Relevância do Ativo
C13: Nível | F13: Descrição
C14: Insignificante | F14: Ativo não afeta processos essenciais e sua perda não gera impacto
C15: Baixo | F15: Ativo auxilia processos, mas sua causa e impacto são facilmente contornáveis.
C16: Significante | F16: É importante para o negócio pois todos os processos passam por ele.
C17: Importante | F17: Ativo essencial para o funcionamento de áreas relevantes; sua perda provoca prejuízo operacional considerável
C18: Crítico | F18: Ativo funcamental para continuidade do negócio; sua indisponibilidade gera paralisação, perdas financeiras e riscos legais.
C20: Severidade das Consequências
C21: Nível | F21: Descrição
C22: Insignificante | F22: Pequena interrupção sem impacto financeiro ou operacional.
C23: Baixa | F23: Impacto limitado e com recuperação rápida; custos pequenos.
C24: Média | F24: Interrupção moderada; pode gerar retrabalho, atrasos e custos notáveis.
C25: Alta | F25: Prejuízo elevado; conpromete operações principais e gera impacto significativo.
C26: Elevada | F26: Prejuízo extremo, paralisação total, danos legais, perda de clientes e reputação.
C28: Impacto
C29: Nível | F29: Descrição
C30: Desprezível | F30: Impacto mínimo, quase imperceptível; sem prejuízo operacional ou financeiro.
C31: Baixo | F31: Pequeno incômodo operacional; custos pequenos; não afeta processos principais.
C32: Significativo | F32: Gera interrupções moderadas, retrabalho, atrasos e impacto financeiro notável.
C33: Importante | F33: Afetam a imagem da organização e causam interrupção de 12 horas nos negócios. A empresa deixa de funcionar/produzir por 12 horas
C34: Desastre | F34: Grande prejuízo financeiro; paralisação total; danos legais severos e fortes crise de reputação.
C36: Critério de Risco
C37: Nível | F37: Descrição
C38: Extremo | F38: A organização pára totalmente seus serviços por mais de 48 horas, impedindo de executar serviços e produzir, afetando sua imagem pública de forma significativa. Prejuízos finaceiros elevados, ações na justiça.
C39: Alto | F39: Risco grave; exige tratamento prioritário e implementação de controles.
C40: Médio | F40: Risco moderado; requer mitigação planejada e monitoramento contínuo.
C41: Baixo | F41: Risco aceitável; manter controles existentes e monitorar periodicamente
C42: Irrelevante | F42: Risco não crítico, porém importante de ser acompanhado; pode exigir ações leves.
C44: Critério de Risco
C45: Nível | F45: Descrição
C46: Extremo | F46: Representa ameaça severa e imediata à continuidade do negócio; não pode ser aceito de forma alguma.
...

Sheet SESSAO_3
A1: Gestão de Riscos de TI – NBR 27005
A3: Sessão 3
A6: OBJETIVO: Compreender e desenvolver o início de um processo de análise de risco e iniciar a identificação dos riscos.
A10: Nas três atividades que fazem parte desta sessão, serão vistos os conceitos apreendidos na sessão 3. | J10: Atividades – Sessão 3
J11: 3.1 Identifique os Ativos
A13: Lembre-se: estas atividades devem ser feitas na sequência e com o acompanhamento da norma 27005. | J13: 3.2 Identifique as Ameaças
J15: 3.3 Identifique os Controles Existentes ou Planejados
A16: Qualquer dúvida pergunte ao instrutor!!

Sheet ATIVOS
A1: Identificação dos Ativos do Escopo
J11: 2.1 Defina o Contexto
K18: Justificativa / Evidências
A20: Ativos Primários | B20: At 01 | C20: Infraestrutura de servidores em nuvem | K20: Essencial para execução dos serviços da empresa. Qualquer indisponibilidade impacta diretamente os clientes.
B21: At 02 | C21: Plataforma de monitoramento SOC 24/7 | K21: Responsável por detectar incidentes de segurança em tempo real. Fundamental para resposta rápida a ameaças.
B22: At 03 | C22: Ferramentas de análise de vulnerabilidades | K22: Utilizadas para identificar falhas nos sistemas dos clientes. São base dos serviços prestados.
B23: At 04 | C23: Sistemas de backup e recuperação de dados | K23: Garantem a continuidade do negócio em caso de falhas ou ataques (ex: ransomware).
B24: At 05 | C24: Código-fonte dos sistemas desenvolvidos | K24: Representa o conhecimento técnico e propriedade intelectual da empresa.
B25: At 06 | C25: Ambientes de desenvolvimento (Dev/Test/Prod) | K25: Separação necessária para garantir qualidade, testes e segurança antes da produção.
B26: At 07 | C26: Banco de dados de clientes corporativos | K26: Contém informações sensíveis e estratégicas, exigindo proteção conforme a LGPD.
B27: At 08 | C27: Logs e registros de segurança (SIEM) | K27: Permitem auditoria, rastreamento de incidentes e investigação de ataques.
B28: At 09 | C28: Ferramentas de pentest (internas e licenciadas) | K28: Essenciais para simulação de ataques e avaliação da segurança dos clientes.
B29: At 10 | C29: Credenciais de acesso (senhas, tokens, chaves API) | K29: Acesso direto a sistemas críticos. Comprometimento pode causar invasões
A32: Ativos de Suporte e Infraestrutura | B32: At 11 | C32: Infraestrutura de rede (firewalls, switches, VPN) | K32: Base da comunicação segura da empresa. Falhas podem expor dados ou interromper serviços
B33: At 12 | C33: Sistemas internos de gestão (ERP/CRM) | K33: Controlam operações administrativas e relacionamento com clientes.
B34: At 13 | C34: Plataforma de atendimento (Help Desk) | K34: Canal direto com clientes para suporte e resolução de incidentes.
B35: At 14 | C35: Contratos e acordos com clientes (SLAs) | K35: Definem responsabilidades, níveis de serviço e obrigações legais.
B36: At 15 | C36: Documentação técnica e procedimentos internos | K36: Padronizam processos e garantem consistência nas operações.
B37: At 16 | C37: Políticas de segurança da informação | K37: Orientam o comportamento dos colaboradores e reduzem riscos de segurança.
B38: At 17 | C38: Ambiente de virtualização (VMs e containers) | K38: Permite escalabilidade e otimização dos recursos computacionais
B39: At 18 | C39: Ferramentas de gestão de projetos (ex: Jira, Trello) | K39: Auxiliam no controle de tarefas, prazos e produtividade das equipes.
B40: At 19 | C40: Dispositivos corporativos (notebooks, desktops) | K40: Utilizados pelos colaboradores, podendo ser ponto de entrada para ataques
B41: At 20 | C41: Sistemas de autenticação (AD, MFA, IAM) | K41: Controlam o acesso aos sistemas, garantindo segurança e rastreabilidade.
B42: At 21 | C42: Repositórios de código (Git, GitHub, GitLab) | K42: Armazenam o código-fonte e histórico de desenvolvimento dos sistemas
B43: At 22 | C43: Plataforma de cloud utilizada (AWS, Azure, etc.) | K43: Base da infraestrutura dos serviços oferecidos pela empresa.
B44: At 23 | C44: Dados sensíveis de clientes (LGPD) | K44: Informações críticas que exigem proteção legal e podem gerar penalidades em caso de vazamento.
... B46: At 25 | C46: Utilizados para troca de informações internas e externas, podendo ser alvo de phishing. | K46: Capital intelectual da empresa, essencial para execução dos serviços e inovação.
B47: At 26
B48: At 27
B49: At 28
B50: At 29
B51: At 30

Sheet LISTA AMEACAS
A1: Identificação das Ameaças aos Ativos
J11: 2.1 Defina o Contexto
B19: Ativos | E19: Ameaça 1 | I19: Ameaças 2 | M19: Justificativa / Evidências
I20: Ameaça 2
A21: =ATIVOS!B20 -> At 01 | B21: =ATIVOS!C20 -> Infraestrutura de servidores em nuvem | E21: Vazamento de informações | I21: Roubo de dados por concorrentes | M21: A empresa lida com dados confidenciais sobre cursos e materiais que são muito importantes para manter o diferencial competitivo. Se não houver controle adequado, pode acontecer vazamento ou até espionagem industrial por parte de concorrentes.
A22: =ATIVOS!B21 -> At 02 | B22: =ATIVOS!C21 -> Plataforma de monitoramento SOC 24/7 | E22: Perda de inovação por acesso indevido | I22: Interferência na produção de novos materiais | M22: As informações sobre tendências de mercado e inovação precisam ser bem protegidas contra acessos não autorizados. Se houver falhas, isso pode atrapalhar o lançamento de novos produtos e afetar a competitividade da empresa.
A23: =ATIVOS!B22 -> At 03 | B23: =ATIVOS!C22 -> Ferramentas de análise de vulnerabilidades | E23: Ataques cibernéticos | I23: Interrupção de serviços críticos | M23: Os sistemas ERP e CRM são fundamentais para o funcionamento da empresa. Se não houver segurança adequada, pode haver paralisação das operações e exposição de dados sensíveis, o que prejudica bastante a organização.
A24: =ATIVOS!B23 -> At 04 | B24: =ATIVOS!C23 -> Sistemas de backup e recuperação de dados | E24: Roubo de informações | I24: Uso indevido por terceiros | M24: Os dados confidenciais dos clientes precisam estar bem protegidos para evitar qualquer violação de privacidade. Isso é importante para seguir leis como a LGPD e manter a confiança dos parceiros e consumidores.
A25: =ATIVOS!B24 -> At 05 | B25: =ATIVOS!C24 -> Código-fonte dos sistemas desenvolvidos | E25: Falhas operacionais | I25: Sabotagem industrial | M25: A produção precisa ser estável. Qualquer ataque ou falha pode comprometer os prazos e a qualidade dos produtos, gerando prejuízos e atrasos.
A26: =ATIVOS!B25 -> At 06 | B26: =ATIVOS!C25 -> Ambientes de desenvolvimento (Dev/Test/Prod) | E26: Interrupção na cadeia logística | I26: Manipulação indevida de entregas | M26: Erros ou atrasos na logística afetam diretamente a satisfação do cliente e podem prejudicar a imagem da empresa KWX.
A27: =ATIVOS!B26 -> At 07 | B27: =ATIVOS!C26 -> Banco de dados de clientes corporativos | E27: Fraudes financeiras | I27: Alteração não autorizada de registros | M27: O setor financeiro lida com transações sensíveis que precisam de segurança contra manipulação ou acessos indevidos.
A28: =ATIVOS!B27 -> At 08 | B28: =ATIVOS!C27 -> Logs e registros de segurança (SIEM) | E28: Falta de conformidade | I28: Desrespeito às normas de segurança | M28: A inexistência de políticas bem estabelecidas pode comprometer a integridade e confidencialidade dos ativos.
A29: =ATIVOS!B28 -> At 09 | B29: =ATIVOS!C28 -> Ferramentas de pentest (internas e licenciadas) | E29: Vazamento de dados pessoais | I29: Uso indevido de informações de colaboradores | M29: Proteção de dados internos é essencial para evitar prejuízos aos funcionários e atender às leis de privacidade.
A30: =ATIVOS!B29 -> At 10 | B30: =ATIVOS!C29 -> Credenciais de acesso (senhas, tokens, chaves API) | E30: Ataques de phishing | I30: Roubo de credenciais | M30: A segurança das comunicações internas e externas é crucial para evitar fraudes e manter a integridade da empresa.
A31: =ATIVOS!B32 -> At 11 | B31: =ATIVOS!C32 -> Infraestrutura de rede (firewalls, switches, VPN) | E31: Falha na infraestrutura | I31: Ataques cibernéticos e invasões | M31: Servidores guardam informações importantes e precisam de proteção contra falhas e acessos não autorizados.
A32: =ATIVOS!B33 -> At 12 | B32: =ATIVOS!C33 -> Sistemas internos de gestão (ERP/CRM) | E32: Malware e ataques de phishing | I32: Uso indevido por funcionários não autorizados | M32: São os principais computadores de trabalho e precisam de proteção contra ataques e perda de dados.
A33: =ATIVOS!B34 -> At 13 | B33: =ATIVOS!C34 -> Plataforma de atendimento (Help Desk) | E33: Acesso indevido a documentos | I33: Sabotagem ou falhas técnicas | M33: Impressoras podem ter documentos secretos e precisam de segurança física e digital.
A34: =ATIVOS!B35 -> At 14 | B34: =ATIVOS!C35 -> Contratos e acordos com clientes (SLAs) | E34: Exploração de vulnerabilidades | I34: Perda de dados por falha sistêmica | M34: São sistemas importantes para a empresa; a segurança deles é vital para evitar problemas e fraudes.
A35: =ATIVOS!B36 -> At 15 | B35: =ATIVOS!C36 -> Documentação técnica e procedimentos internos | E35: Furto de mídia ou documentos | I35: Recuperação de mídia reciclada ou descartada | M35: Pode expor procedimentos internos e informações críticas; Documentos descartados podem ser recuperados indevidamente.
A36: =ATIVOS!B37 -> At 16 | B36: =ATIVOS!C37 -> Políticas de segurança da informação | E36: Violação das condições de uso do sistema de informação que possibilitam sua manutenção | I36: Abuso de direitos | M36: Colaboradores podem descumprir políticas estabelecidas; Usuários com acesso podem agir fora das regras definidas.
A37: =ATIVOS!B38 -> At 17 | B37: =ATIVOS!C38 -> Ambiente de virtualização (VMs e containers) | E37: Falha de equipamento | I37: Alteração do software | M37: Pode derrubar máquinas virtuais e serviços; Pode comprometer o funcionamento das VMs ou containers.
A38: =ATIVOS!B39 -> At 18 | B38: =ATIVOS!C39 -> Ferramentas de gestão de projetos (ex: Jira, Trello) | E38: Saturação do sistema de informação | I38: Processamento ilegal de dados | M38: Pode tornar a ferramenta indisponível; Pode ocorrer uso indevido das informações dos projetos.
A39: =ATIVOS!B40 -> At 19 | B39: =ATIVOS!C40 -> Dispositivos corporativos (notebooks, desktops) | E39: Furto de equipamentos | I39: Uso não autorizado de equipamento | M39: Pode expor dados armazenados nos dispositivos; Terceiros podem acessar informações da empresa.
A40: =ATIVOS!B41 -> At 20 | B40: =ATIVOS!C41 -> Sistemas de autenticação (AD, MFA, IAM) | E40: Abuso de direitos | I40: Comprometimento dos dados | M40: Usuários podem utilizar privilégios de forma indevida
A41: =ATIVOS!B42 -> At 21 | B41: =ATIVOS!C42 -> Repositórios de código (Git, GitHub, GitLab) | E41: Cópia ilegal de software | I41: Alteração do software | M41: Código pode ser copiado sem autorização; Código pode ser modificado de forma maliciosa.
A42: =ATIVOS!B43 -> At 22 | B42: =ATIVOS!C43 -> Plataforma de cloud utilizada (AWS, Azure, etc.) | E42: Interrupção do suprimento de energia | I42: Falha de equipamento | M42: Pode causar indisponibilidade dos serviços; Problemas na infraestrutura podem afetar sistemas hospetados.
... A45: =ATIVOS!B46 -> At 25 | B45: =ATIVOS!C46 -> Utilizados para troca de informações internas e externas, podendo ser alvo de phishing. | E45: Indisponibilidade de recursos humanos | I45: Falha de equipamento | M45: A ausência ou saída de colaboradores pode comprometer atividades críticas, já que o conhecimento técnico está concentrado na equipe; Falhas de equipamento podem causar incidentes de segurança ou operacionais, impactando os serviços da empresa.
A46: =ATIVOS!B47 -> At 26 | B46: =ATIVOS!C47 -> 0 | E46: Identifique uma Ameaça | I46: Identifique uma Ameaça
A47: =ATIVOS!B48 -> At 27 | B47: =ATIVOS!C48 -> 0 | E47: Identifique uma Ameaça | I47: Identifique uma Ameaça
A48: =ATIVOS!B49 -> At 28 | B48: =ATIVOS!C49 -> 0 | E48: Identifique uma Ameaça | I48: Identifique uma Ameaça
A49: =ATIVOS!B50 -> At 29 | B49: =ATIVOS!C50 -> 0 | E49: Identifique uma Ameaça | I49: Identifique uma Ameaça
A50: =ATIVOS!B51 -> At 30 | B50: =ATIVOS!C51 -> 0 | E50: Identifique uma Ameaça | I50: Identifique uma Ameaça

Sheet CONTROLES EXIST
A1: Identificação dos Controles Existentes ou com Implementação Planejada
J11: 2.1 Defina o Contexto
B19: Ativo | E19: Ameaças | J19: Controle Existente ou Planejado | M19: Justificativa/Evidências
A20: ='LISTA AMEACAS'!A21 -> At 01 | B20: ='LISTA AMEACAS'!B21 -> Infraestrutura de servidores em nuvem | E20: ='LISTA AMEACAS'!E21 -> Vazamento de informações | H20: Controle | J20: Planejado | M20: Implementação de controle de acesso e criptografia para proteger dados sensíveis armazenados na nuvem; A criptografia protege os dados armazenados e transmitidos contra acessos não autorizados.
H21: Controle | J21: Planejado | M21: Monitoramento contínuo e auditoria de logs permitem identificar acessos suspeitos e prevenir vazamentos de informações; O monitoramento contínuo permite detectar comportamentos suspeitos e prevenir incidentes de segurança.
E22: ='LISTA AMEACAS'!I21 -> Roubo de dados por concorrentes | H22: Controle | J22: Planejado | M22: Criptografia de dados em trânsito e repouso; A proteção de dados em trânsito e repouso dificulta a interceptação por terceiros.
H23: Controle | J23: Planejado | M23: A implementação de autentitação multifator reduz o risco de acesso indevido; A autenticação multifator reduz o risco de acesso indevido mesmo com credenciais comprometidas.
B25: Ativo | E25: Ameaças | J25: Controle Existente ou Planejado | M25: Justificativa/Evidências
A26: ='LISTA AMEACAS'!A22 -> At 02 | B26: ='LISTA AMEACAS'!B22 -> Plataforma de monitoramento SOC 24/7 | E26: ='LISTA AMEACAS'!E22 -> Perda de inovação por acesso indevido | H26: Controle | J26: Planejado | M26: Restrição de acesso a informações estratégicas; A restrição de acesso protege informações estratégicas da empresa.
H27: Controle | J27: Planejado | M27: A segregação de acessos garante que apenas usuários autorizados manipulem informações; A segregação de funções impede que usuários acessem dados fora de sua responsabilidade.
E28: ='LISTA AMEACAS'!I22 -> Interferência na produção de novos materiais | H28: Controle | J28: Existente | M28: Padronização de processos; A padronização de processos reduz erros operacionais e inconsistências.
H29: Controle | J29: Planejado | M29: Monitoramento de atividades; O monitoramento das atividades permite identificar e corrigir falhas rapidamente.
B31: Ativo | E31: Ameaças | J31: Controle Existente ou Planejado | M31: Justificativa/Evidências
A32: ='LISTA AMEACAS'!A23 -> At 03 | B32: ='LISTA AMEACAS'!B23 -> Ferramentas de análise de vulnerabilidades | E32: ='LISTA AMEACAS'!E23 -> Ataques cibernéticos | H32: Controle | J32: Existente | M32: Uso de ferramentas de segurança; O uso de ferramentas de segurança permite identificar vulnerabilidades e reduzir a exposição a ataques cibernéticos.
H33: Controle | J33: Planejado | M33: Atualização contínua e monitoramento; A atualização contínua e o monitoramento garantem que novas ameaças sejam detectadas e mitigadas rapidamente.
E34: ='LISTA AMEACAS'!I23 -> Interrupção de serviços críticos | H34: Controle | J34: Planejado | M34: Redundância; A implementação de redundância assegura a disponibilidade dos sistemas mesmo em caso de falhas.
H35: Controle | J35: Planejado | M35: Plano de continuidade; O plano de continuidade garante a rápida recuperação dos serviços, reduzindo impactos operacionais.
B37: Ativo | E37: Ameaças | J37: Controle Existente ou Planejado | M37: Justificativa/Evidências
A38: ='LISTA AMEACAS'!A24 -> At 04 | B38: ='LISTA AMEACAS'!B24 -> Sistemas de backup e recuperação de dados | E38: ='LISTA AMEACAS'!E24 -> Roubo de informações | H38: Controle | J38: Existente | M38: Backup de dados; A realização de backups periódicos garante a recuperação dos dados em caso de incidentes de segurança.
H39: Controle | J39: Planejado | M39: Criptografia dos backups; A criptografia dos backups protege as informações contra acesso não autorizado.
E40: ='LISTA AMEACAS'!I24 -> Uso indevido por terceiros | H40: Controle | J40: Planejado | M40: Controle de acesso; Controle de acesso restringe a utilização dos dados apenas a usuários autorizados.
H41: Controle | J41: Planejado | M41: Auditoria de acessos; A auditoria de acessos permite rastrear atividades e identificar possíveis usos indevidos.
B43: Ativo | E43: Ameaças | J43: Controle Existente ou Planejado | M43: Justificativa/Evidências
A44: ='LISTA AMEACAS'!A25 -> At 05 | B44: ='LISTA AMEACAS'!B25 -> Código-fonte dos sistemas desenvolvidos | E44: ='LISTA AMEACAS'!E25 -> Falhas operacionais | H44: Controle | J44: Existente | M44: Testes básicos; A realização de testes básicos permite identificar erros no sistema antes da implantação em produção.
H45: Controle | J45: Planejado | M45: Revisão formal de código; A revisão formal de código garante maior qualidade e reduz a ocorrência de falhas operacionais.
E46: ='LISTA AMEACAS'!I25 -> Sabotagem industrial | H46: Controle | J46: Planejado | M46: Controle de acesso ao repositório; O controle de acesso ao repositório restringe alterações apenas a usuários autorizados.
H47: Controle | J47: Planejado | M47: Monitoramento de alterações; O monitoramento de alterações permite identificar modificações suspeitas no código-fonte.
B49: Ativo | E49: Ameaças | J49: Controle Existente ou Planejado | M49: Justificativa/Evidências
A50: ='LISTA AMEACAS'!A26 -> At 06 | B50: ='LISTA AMEACAS'!B26 -> Ambientes de desenvolvimento (Dev/Test/Prod) | E50: ='LISTA AMEACAS'!E26 -> Interrupção na cadeia logística | H50: Controle | J50: Planejado | M50: Plano de continuidade; O plano de continuidade garante a manutenção das operações mesmo em caso de falhas nos ambientes.
H51: Controle | J51: Planejado | M51: Monitoramento; O monitoramento contínuo permite identificar problemas rapidamente e reduzir impactos no fluxo de desenvolvimento.
E52: ='LISTA AMEACAS'!I26 -> Manipulação indevida de entregas | H52: Controle | J52: Existente | M52: Controle de versionamento; O controle de versionamento garante a integridade das versões e evita alterações não autorizadas.
H53: Controle | J53: Planejado | M53: Rastreamento de alterações; O rastreamento de alterações permite a identificar responsáveis por modificações indevidas.
B55: Ativo | E55: Ameaças | J55: Controle Existente ou Planejado | M55: Justificativa/Evidências
A56: ='LISTA AMEACAS'!A27 -> At 07 | B56: ='LISTA AMEACAS'!B27 -> Banco de dados de clientes corporativos | E56: ='LISTA AMEACAS'!E27 -> Fraudes financeiras | H56: Controle | J56: Planejado | M56: Auditoria; A realização de auditorias permite identificar inconsistências e previnir fraudes nos dados financeiros.
H57: Controle | J57: Planejado | M57: Segregação de funções; A segregação de funções reduz o risco de ações maliciosas ao limitar o acesso conforme responsabilidades.
E58: ='LISTA AMEACAS'!I27 -> Alteração não autorizada de registros | H58: Controle | J58: Existente | M58: Controle de acesso; controle de acesso garante que apenas usuários autorizados possam modificar os dados.
H59: Controle | J59: Planejado | M59: Logs e monitoramento; O uso de logs e monitoramento permite rastrear alterações e identificar atividades suspeitas.
B61: Ativo | E61: Ameaças | J61: Controle Existente ou Planejado | M61: Justificativa/Evidências
A62: ='LISTA AMEACAS'!A28 -> At 08 | B62: ='LISTA AMEACAS'!B28 -> Logs e registros de segurança (SIEM) | E62: ='LISTA AMEACAS'!E28 -> Falta de conformidade | H62: Controle | J62: Planejado | M62: Políticas de segurança; A definição de políticas de segurança assegura que os processos estejam alinhados às normas e regulamentações.
H63: Controle | J63: Planejado | M63: Auditorias; A realização de auditorias periódicas garante o cumprimento das exigências de conformidade.
...

Sheet SESSAO_4
A1: Gestão de Riscos de TI – NBR 27005
A3: Sessão 4
A6: OBJETIVO: Aplicar num exercício os conhecimentos adquiridos na sessão 4. Compreender e desenvolver a identificação dos riscos.
A10: Nas duas atividades que fazem parte desta sessão, serão vistos os conceitos apreendidos na sessão 4. | J10: Atividades – Sessão 4
J11: 4.1 Identifique as Vulnerabilidades
A13: Lembre-se: estas atividades devem ser feitas na sequência e com o acompanhamento da norma 27005. | J13: 4.2 Identifique as Consequencias
A16: Qualquer dúvida pergunte ao instrutor!!

Sheet VULNERABILIDADES
A1: Identificação das Vulnerabilidades NÃO Atendidas pelos Controles Existentes
J11: 2.1 Defina o Contexto
B19: Ativo | D19: Ameaças | I19: Controle existente | K19: Nr. | L19: Vulnerabilidades Encontradas | S19: Justificativa/Evidências
A20: At 01 | B20: ='LISTA AMEACAS'!B21 -> Infraestrutura de servidores em nuvem | D20: ='LISTA AMEACAS'!E21 -> Vazamento de informações | G20: Controle | I20: ='CONTROLES EXIST'!J20 -> Planejado | K20: 1 | L20: Falta de classificação da informação | S20: Não há política de classificação de dados implementada, evidenciado pela ausência de identificação de níveis de criticidade nos documentos.
K21: 2 | L21: Dados armazenados sem criptografia. | S21: Arquivos e bases de dados estão acessíveis sem mecanismos de criptografia em repouso, permitindo leitura direta em caso de acesso indevido.
G22: Controle | I22: ='CONTROLES EXIST'!J21 -> Planejado | K22: 3 | L22: Armazenamento inseguro | S22: Dados armazenados em locais sem controle de acesso.conforme estruturas de diretórios compartilhados.
K23: 4 | L23: Falta de monitoramento de acesso. | S23: Não há registro ou análise de logs de acesso aos dados armazenados.
D24: ='LISTA AMEACAS'!I21 -> Roubo de dados por concorrentes | G24: Controle | I24: ='CONTROLES EXIST'!J22 -> Planejado | K24: 5 | L24: Falta de backup adequado | S24: Existe backup porém sem validação periódica de restauração
G25: Controle | K25: 6 | L25: Logs de auditoria incompletos. | S25: Atividades críticas não são registradas de forma detalhada, dificultando rastreabilidade.
G26: Controle | I26: ='CONTROLES EXIST'!J23 -> Planejado | K26: 7 | L26: Acesso indevido | S26: Permissões amplas sem segregação,evidenciado por ausência de controle por perfil.
K27: 8 | L27: Armazenamento de credenciais em texto simples. | S27: Credenciais são armazenadas sem criptografia, facilitando comprometimento.
B29: Ativo | D29: Ameaças | I29: Controle existente | K29: Nr. | L29: Vulnerabilidades Encontradas | S29: Justificativa/Evidências
A30: ='LISTA AMEACAS'!A22 -> At 02 | B30: ='LISTA AMEACAS'!B22 -> Plataforma de monitoramento SOC 24/7 | D30: ='LISTA AMEACAS'!E22 -> Perda de inovação por acesso indevido | G30: Controle | I30: ='CONTROLES EXIST'!J26 -> Planejado | K30: 1 | L30: Documentos técnicos e projetos podem ser acessados sem restrições adequadas. | S30: Não há sistema de rastreamento de acessos que registre todas as interações com documentos.
K31: 2 | L31: Sistemas desatualizados. | S31: A plataforma utiliza versões antigas sem atualizações frequentes.
G32: Controle | I32: ='CONTROLES EXIST'!J27 -> Planejado | K32: 3 | L32: Dependência de tecnologias obsoletas. | S32: Ferramentas utilizadas não acompanham padrões atuais de mercado.
K33: 4 | L33: Falta de capacitação da equipe. | S33: Equipe não recebe treinamentos periódicos em novas tecnologias.
D34: ='LISTA AMEACAS'!I22 -> Interferência na produção de novos materiais | G34: Controle | I34: ='CONTROLES EXIST'!J28 -> Existente | K34: 5 | L34: Acesso indevido à plataforma. | S34: Falta de mecanismos de controle que garantam que apenas usuários autorizados possam modificar materiais de pesquisa.
G35: Controle | K35: 6 | L35: Configuração inadequada dos sensores. | S35: Sensores não detectam ameaças por configuração incorreta.
G36: Controle | I36: ='CONTROLES EXIST'!J29 -> Planejado | K36: 7 | L36: Alertas não tratados adequadamente. | S36: Eventos críticos não são analisados em tempo hábil.
K37: 8 | L37: Falta de segregação de ambientes | S37: Ambientes de teste e produção utilizam os mesmos recursos e permissões.
B39: Ativo | D39: Ameaças | I39: Controle existente | K39: Nr. | L39: Vulnerabilidades Encontradas | S39: Justificativa/Evidências
A40: ='LISTA AMEACAS'!A23 -> At 03 | B40: ='LISTA AMEACAS'!B23 -> Ferramentas de análise de vulnerabilidades | D40: ='LISTA AMEACAS'!E23 -> Ataques cibernéticos | G40: Controle | I40: ='CONTROLES EXIST'!J32 -> Existente | K40: 1 | L40: Falta de proteção robusta contra ameaças externas, como hackers e malware. | S40: Empresas do setor já sofreram ataques que comprometeram dados financeiros e operacionais.
K41: 2 | L41: Ferramentas desatualizadas. | S41: Base de vulnerabilidades não é atualizada regularmente.
G42: Controle | I42: ='CONTROLES EXIST'!J33 -> Planejado | K42: 3 | L42: Execução sem autenticação forte. | S42: Acesso administrativo sem MFA.
K43: 4 | L43: Resultados armazenados sem proteção. | S43: Relatórios ficam acessíveis sem controle.
D44: ='LISTA AMEACAS'!I23 -> Interrupção de serviços críticos | G44: Controle | I44: ='CONTROLES EXIST'!J34 -> Planejado | K44: 5 | L44: Falhas nos servidores podem levar à indisponibilidade dos sistemas empresariais. | S44: Registros de incidentes mostram tempos de indisponibilidade que afetaram operações internas.
G45: Controle | K45: 6 | L45: Dependência de único servidor. | S45: Ferramenta roda em apenas um ambiente sem redundância.
G46: Controle | I46: ='CONTROLES EXIST'!J35 -> Planejado | K46: 7 | L46: Falta de redundância. | S46: Não há sistema de contingência.
K47: 8 | L47: Acesso administrativo compartilhado. | S47: Várias pessoas utilizam a mesma conta administrativa.
B49: Ativo | D49: Ameaças | I49: Controle existente | K49: Nr. | L49: Vulnerabilidades Encontradas | S49: Justificativa/Evidências
A50: ='LISTA AMEACAS'!A24 -> At 04 | B50: ='LISTA AMEACAS'!B24 -> Sistemas de backup e recuperação de dados | D50: ='LISTA AMEACAS'!E24 -> Roubo de informações | G50: Controle | I50: ='CONTROLES EXIST'!J38 -> Existente | K50: 1 | L50: Acesso não autorizado pode comprometer dados sensíveis dos clientes. | S50: Empresas do setor já sofreram vazamentos de dados, causando danos à reputação e penalidades legais.
K51: 2 | L51: Falta de logs de acesso. | S51: Não há rastreamento de quem acessa os backups.
G52: Controle | I52: ='CONTROLES EXIST'!J39 -> Planejado | K52: 3 | L52: Armazenamento inadequado. | S52: Backups ficam em locais sem proteção adequada.
K53: 4 | L53: Acesso amplo aos backups. | S53: Vários usuários possuem acesso sem necessidade.
D54: ='LISTA AMEACAS'!I24 -> Uso indevido por terceiros | G54: Controle | I54: ='CONTROLES EXIST'!J40 -> Planejado | K54: 5 | L54: Parceiros ou funcionários podem acessar e utilizar dados de clientes sem autorização adequada. | S54: Não há um sistema claro de rastreamento de uso de dados por terceiros.
G55: Controle | K55: 6 | L55: Ausência de trilhas de auditoria sobre restaurações e consultas. | S55: O sistema não registra quem acessou, restaurou ou fez download de backups, impossibilitando identificar uso indevido.
G56: Controle | I56: ='CONTROLES EXIST'!J41 -> Planejado | K56: 7 | L56: Ausência de mecanismos eficazes de autenticação forte (MFA). | S56: O acesso aos sistemas ocorre apenas por login e senha, sem autenticação multifator, aumentando significativamente o risco de comprometimento por credenciais vazadas ou ataques de força bruta.
K57: 8 | L57: Falta de políticas formais de uso e proteção da informação. | S57: Não existem diretrizes claras e formalizadas sobre o uso, compartilhamento e proteção dos dados, o que aumenta o risco de exposição indevida por usuários internos ou terceiros com acesso ao ambiente.
B59: Ativo | D59: Ameaças | I59: Controle existente | K59: Nr. | L59: Vulnerabilidades Encontradas | S59: Justificativa/Evidências
A60: ='LISTA AMEACAS'!A25 -> At 05 | B60: ='LISTA AMEACAS'!B25 -> Código-fonte dos sistemas desenvolvidos | D60: ='LISTA AMEACAS'!E25 -> Falhas operacionais | G60: Controle | I60: ='CONTROLES EXIST'!J44 -> Existente | K60: 1 | L60: Erros mecânicos ou falhas humanas podem interromper o fluxo produtivo. | S60: Registros internos mostram tempos de inatividade devido a falhas técnicas.
...

Sheet CONSEQUENCIAS
A1: Identificação das Consequências das Vulnerabilidades Levantadas
J11: 2.1 Defina o Contexto
B19: Ativo | D19: Ameaças | I19: Controle existente | L19: Nr. | M19: Vulnerabilidades Encontradas | P19: Consequências | T19: Justificativa/Evidências | AC19: Defina uma consequência:
A20: ='LISTA AMEACAS'!A21 -> At 01 | B20: ='LISTA AMEACAS'!B21 -> Infraestrutura de servidores em nuvem | D20: ='LISTA AMEACAS'!E21 -> Vazamento de informações | G20: Controle | I20: ='CONTROLES EXIST'!J20 -> Planejado | L20: 1 | M20: =VULNERABILIDADES!L20 -> Falta de classificação da informação | P20: Perda de Autenticidade | T20: A ausência de classificação adequada dos dados pode levar ao tratamento indevido de informações sensíveis, resultando em exposição não autorizada, vazamentos acidentais e utilização inadequada dos documentos, comprometendo a confidencialidade e a integridade das informações institucionais. | AC20: Perda de Confidencialidade
L21: 2 | M21: =VULNERABILIDADES!L21 -> Dados armazenados sem criptografia. | P21: Perda de Integridade | T21: A falta de criptografia possibilita que qualquer acesso não autorizado resulte na leitura integral dos dados, aumentando o risco de vazamento de informações sensíveis, comprometimento da privacidade, incidentes de segurança e danos institucionais decorrentes da exposição de conteúdo confidencial. | AC21: Perda de Integridade
G22: Controle | I22: ='CONTROLES EXIST'!J21 -> Planejado | L22: 3 | M22: =VULNERABILIDADES!L22 -> Armazenamento inseguro | P22: Perda de confidencialidade | T22: O armazenamento inadequado permite que usuários sem autorização acessem, alterem ou excluam informações, causando risco de perda de dados, manipulação indevida e exposição de conteúdo sensível, comprometendo a integridade e a confidencialidade das informações institucionais. | AC22: Perda de Disponibilidade
L23: 4 | M23: =VULNERABILIDADES!L23 -> Falta de monitoramento de acesso. | P23: Perda de Autenticidade | T23: Impossibilidade de rastrear e identificar ações realizadas sobre os dados armazenados, dificultando a detecção de acessos não autorizados e comprometendo a resposta a incidentes de segurança, além de aumentar o risco de vazamento ou manipulação indevida das informações sem responsabilização dos autores. | AC23: Perda de Autenticidade
D24: ='LISTA AMEACAS'!I21 -> Roubo de dados por concorrentes | G24: Controle | I24: ='CONTROLES EXIST'!J22 -> Planejado | L24: 5 | M24: =VULNERABILIDADES!L24 -> Falta de backup adequado | P24: Perda de Disponibilidade | T24: Risco de indisponibilidade ou perda definitiva de dados em caso de falhas, ataques ou corrupção de arquivos, uma vez que a ausência de testes de restauração impede a garantia de que os backups são realmente recuperáveis, podendo comprometer a continuidade das operações e a recuperação dos sistemas dentro do tempo necessário. | AC24: Prejuizo financeiro por retrabalho
L25: 6 | M25: =VULNERABILIDADES!L25 -> Logs de auditoria incompletos. | P25: Perda de Autenticidade | T25: Comprometimento da capacidade de auditoria e investigação de incidentes, pois a ausência de registros completos impede a reconstrução precisa das ações realizadas em sistemas críticos, dificultando a identificação de responsáveis por falhas, acessos indevidos ou alterações não autorizadas, além de enfraquecer o controle interno e a conformidade com normas de segurança da informação. | AC25: Afeta imagem e reputação
G26: Controle | I26: ='CONTROLES EXIST'!J23 -> Planejado | L26: 7 | M26: =VULNERABILIDADES!L26 -> Acesso indevido | P26: Perda de Integridade | T26: Aumento significativo do risco de acesso não autorizado a dados e sistemas críticos, permitindo que usuários executem funções além de suas responsabilidades, o que pode levar a alterações indevidas, vazamento de informações sensíveis e comprometimento da integridade e confidencialidade dos dados, além de dificultar a responsabilização em caso de incidentes de segurança.
L27: 8 | M27: =VULNERABILIDADES!L27 -> Armazenamento de credenciais em texto simples. | P27: Perda de confidencialidade | T27: Possibilidade de exposição direta de senhas e credenciais em caso de acesso indevido aos sistemas ou bases de dados, facilitando o comprometimento de contas e sistemas.
B29: Ativo | D29: Ameaças | I29: Controle existente | L29: Nr. | M29: Vulnerabilidades Encontradas | P29: Consequências | T29: Justificativa/Evidências
A30: ='LISTA AMEACAS'!A22 -> At 02 | B30: ='LISTA AMEACAS'!B22 -> Plataforma de monitoramento SOC 24/7 | D30: ='LISTA AMEACAS'!E22 -> Perda de inovação por acesso indevido | G30: Controle | I30: Insuficiente | L30: 1 | M30: Documentos técnicos e projetos podem ser acessados sem restrições adequadas. | P30: Perda de confidencialidade | T30: Exposição de informações técnicas e estratégicas a usuários não autorizados, aumentando o risco de cópia, uso indevido ou vazamento de dados sensíveis, além de impossibilitar a identificação de quem acessou ou alterou os documentos
L31: 2 | M31: Sistemas desatualizados. | P31: Perda de Disponibilidade | T31: Aumento da exposição a falhas conhecidas e vulnerabilidades já corrigidas em versões mais recentes, facilitando ataques, invasões e exploração de brechas de segurança, podendo causar indisponibilidade dos sistemas ou comprometimento de dados
G32: Controle | I32: Insuficiente | L32: 3 | M32: Dependência de tecnologias obsoletas. | P32: Perda de Disponibilidade | T32: Limitação na manutenção, atualização e integração dos sistemas, aumentando a probabilidade de falhas operacionais e dificuldades na correção de vulnerabilidades, o que pode levar à interrupção dos serviços e falhas no funcionamento das aplicações
L33: 4 | M33: Falta de capacitação da equipe. | P33: Prejuizo financeiro por retrabalho | T33: Maior probabilidade de erros operacionais, uso incorreto de sistemas e falhas na aplicação de boas práticas de segurança, o que pode gerar retrabalho, atrasos nas atividades e redução da eficiência dos processos
D34: ='LISTA AMEACAS'!I22 -> Interferência na produção de novos materiais | G34: Controle | I34: Insuficiente | L34: 5 | M34: Acesso indevido à plataforma. | P34: Perda de Integridade | T34: Possibilidade de alterações não autorizadas nos materiais de pesquisa durante sua produção, comprometendo a qualidade, a consistência e a confiabilidade dos conteúdos desenvolvidos, o que pode gerar retrabalho, atrasos nos projetos e perda de credibilidade das informações
L35: 6 | M35: Configuração inadequada dos sensores. | P35: Perda de Disponibilidade | T35: Falha na detecção de eventos ou atividades suspeitas devido à configuração incorreta dos sensores, permitindo que ameaças não sejam identificadas em tempo hábil e impactem a operação dos sistemas,
G36: Controle | I36: Existente, porém desatualizado | L36: 7 | M36: Alertas não tratados adequadamente. | P36: Perda de Disponibilidade | T36: traso na identificação e resposta a incidentes de segurança, permitindo que ameaças evoluam e causem impactos maiores nos sistemas e operações, comprometendo a continuidade dos serviços.
L37: 8 | M37: Falta de segregação de ambientes | P37: Perda de Disponibilidade | T37: Possibilidade de alterações ou falhas em ambiente de teste impactarem diretamente o ambiente de produção, causando interrupções nos serviços e instabilidade dos sistemas.
B39: Ativo | D39: Ameaças | I39: Controle existente | L39: Nr. | M39: Vulnerabilidades Encontradas | P39: Consequências | T39: Justificativa/Evidências
A40: ='LISTA AMEACAS'!A23 -> At 03 | B40: ='LISTA AMEACAS'!B23 -> Ferramentas de análise de vulnerabilidades | D40: ='LISTA AMEACAS'!E23 -> Ataques cibernéticos | G40: Controle | I40: ='CONTROLES EXIST'!J32 -> Existente | L40: 1 | M40: =VULNERABILIDADES!L40 -> Falta de proteção robusta contra ameaças externas, como hackers e malware. | P40: Perda de confidencialidade | T40: Possibilidade de invasões aos sistemas com acesso não autorizado a dados financeiros e operacionais, além de interrupção de serviços e vazamento de informações sensíveis.
L41: 2 | M41: =VULNERABILIDADES!L41 -> Ferramentas desatualizadas. | P41: Perda de Disponibilidade | T41: Incapacidade de identificar novas ameaças e falhas conhecidas, permitindo que atacantes explorem vulnerabilidades já corrigidas em atualizações recentes, aumentando o risco de invasão e comprometimento dos sistemas
G42: Controle | I42: ='CONTROLES EXIST'!J33 -> Planejado | L42: 3 | M42: =VULNERABILIDADES!L42 -> Execução sem autenticação forte. | P42: Perda de confidencialidade | T42: Facilitação de invasões por meio de credenciais comprometidas, permitindo que atacantes assumam contas administrativas e executem ações críticas nos sistemas sem barreiras adicionais de segurança.
L43: 4 | M43: =VULNERABILIDADES!L43 -> Resultados armazenados sem proteção. | P43: Perda de confidencialidade | T43: Exposição de relatórios e informações sensíveis a usuários não autorizados ou atacantes, facilitando vazamento de dados estratégicos e operacionais
D44: ='LISTA AMEACAS'!I23 -> Interrupção de serviços críticos | G44: Controle | I44: ='CONTROLES EXIST'!J34 -> Planejado | L44: 5 | M44: =VULNERABILIDADES!L44 -> Falhas nos servidores podem levar à indisponibilidade dos sistemas empresariais. | P44: Perda de Disponibilidade | T44: Paralisação total ou parcial dos sistemas empresariais devido a falhas em servidores, impactando diretamente a continuidade das operações internas e causando atrasos em processos essenciais
L45: 6 | M45: =VULNERABILIDADES!L45 -> Dependência de único servidor. | P45: Perda de Disponibilidade | T45: Indisponibilidade total dos sistemas em caso de falha do servidor principal, pois não há ambiente redundante para continuidade das operações, causando paralisação dos serviços críticos
G46: Controle | I46: ='CONTROLES EXIST'!J35 -> Planejado | L46: 7 | M46: =VULNERABILIDADES!L46 -> Falta de redundância. | P46: Perda de Disponibilidade | T46: Impossibilidade de continuidade dos serviços em caso de falhas ou indisponibilidade do ambiente principal, já que não existe sistema de contingência para assumir as operações, causando paralisação das atividades essenciais
L47: 8 | M47: =VULNERABILIDADES!L47 -> Acesso administrativo compartilhado. | P47: Perda de Disponibilidade | T47: Dificuldade de rastrear ações realizadas no sistema e identificar a origem de alterações ou falhas, aumentando o risco de erros operacionais que podem causar indisponibilidade dos serviços críticos
B49: Ativo | D49: Ameaças | I49: Controle existente | L49: Nr. | M49: Vulnerabilidades Encontradas | P49: Consequências | T49: Justificativa/Evidências
A50: ='LISTA AMEACAS'!A24 -> At 04 | B50: ='LISTA AMEACAS'!B24 -> Sistemas de backup e recuperação de dados | D50: ='LISTA AMEACAS'!E24 -> Roubo de informações | G50: Controle | I50: ='CONTROLES EXIST'!J38 -> Existente | L50: 1 | M50: =VULNERABILIDADES!L50 -> Acesso não autorizado pode comprometer dados sensíveis dos clientes. | P50: Perda de confidencialidade | T50: Exposição e vazamento de dados sensíveis de clientes por acessos não autorizados, comprometendo a confidencialidade das informações e podendo gerar impactos legais e reputacionais para a organização
L51: 2 | M51: =VULNERABILIDADES!L51 -> Falta de logs de acesso. | P51: Perda de confidencialidade | T51: Impossibilidade de identificar quem acessou ou manipulou os backups, facilitando acessos indevidos e possíveis vazamentos de dados sem detecção ou responsabilização
G52: Controle | I52: ='CONTROLES EXIST'!J39 -> Planejado | L52: 3 | M52: =VULNERABILIDADES!L52 -> Armazenamento inadequado. | P52: Perda de confidencialidade | T52: Exposição dos backups a acessos não autorizados ou extração indevida de dados sensíveis devido à falta de proteção no armazenamento, facilitando vazamentos de informações críticas
L53: 4 | M53: =VULNERABILIDADES!L53 -> Acesso amplo aos backups. | P53: Perda de confidencialidade | T53: Aumento do risco de acesso indevido e extração de dados sensíveis armazenados em backups por usuários não autorizados ou desnecessariamente privilegiados, facilitando vazamentos de informações críticas
D54: ='LISTA AMEACAS'!I24 -> Uso indevido por terceiros | G54: Controle | I54: ='CONTROLES EXIST'!J40 -> Planejado | L54: 5 | M54: =VULNERABILIDADES!L54 -> Parceiros ou funcionários podem acessar e utilizar dados de clientes sem autorização adequada. | P54: Perda de confidencialidade | T54: Possibilidade de utilização indevida de dados de clientes por terceiros sem autorização ou controle, dificultando a identificação de quem acessou e como os dados foram utilizados
L55: 6 | M55: =VULNERABILIDADES!L55 -> Ausência de trilhas de auditoria sobre restaurações e consultas. | P55: Perda de confidencialidade | T55: Impossibilidade de rastrear ações realizadas sobre os backups, como acessos, restaurações ou downloads, dificultando a detecção de uso indevido por terceiros e comprometendo o controle sobre dados sensíveis
G56: Controle | I56: ='CONTROLES EXIST'!J41 -> Planejado | L56: 7 | M56: =VULNERABILIDADES!L56 -> Ausência de mecanismos eficazes de autenticação forte (MFA). | P56: Perda de confidencialidade | T56: Facilitação do acesso não autorizado aos sistemas por terceiros mediante uso de credenciais comprometidas ou ataques de força bruta, permitindo a utilização indevida de dados e recursos sem camadas adicionais de verificação
L57: 8 | M57: =VULNERABILIDADES!L57 -> Falta de políticas formais de uso e proteção da informação. | P57: Perda de confidencialidade | T57: Uso inadequado ou não autorizado de informações sensíveis por falta de regras e controle definidos, facilitando o compartilhamento indevido de dados por usuários internos ou terceiros com acesso ao ambiente
B59: Ativo | D59: Ameaças | I59: Controle existente | L59: Nr. | M59: Vulnerabilidades Encontradas | P59: Consequências | T59: Justificativa/Evidências
